[{"name": "test.test_helloweb.HelloTest.test_message", "status": "errored", "message": "'charmap' codec can't encode character '\\U0001f7e1' in position 0: character maps to <undefined>", "passed": false, "points": ["2.4.1", "2.4.2", "2.4.3", "2.4.4", "2.4.5"], "backtrace": ["  File \"C:\\Program Files\\WindowsApps\\PythonSoftwareFoundation.Python.3.10_3.10.2800.0_x64__qbz5n2kfra8p0\\lib\\unittest\\case.py\", line 59, in testPartExecutor\n    yield\n", "  File \"C:\\Program Files\\WindowsApps\\PythonSoftwareFoundation.Python.3.10_3.10.2800.0_x64__qbz5n2kfra8p0\\lib\\unittest\\case.py\", line 591, in run\n    self._callTestMethod(testMethod)\n", "  File \"C:\\Program Files\\WindowsApps\\PythonSoftwareFoundation.Python.3.10_3.10.2800.0_x64__qbz5n2kfra8p0\\lib\\unittest\\case.py\", line 549, in _callTestMethod\n    method()\n", "  File \"C:\\Users\\khali\\AppData\\Local\\tmc\\vscode\\mooc-securing-software-23\\part2-10.hellowebwithdatabase\\test\\test_helloweb.py\", line 24, in test_message\n    response = self.client.get('/', {'id': i})\n", "  File \"C:\\Users\\khali\\AppData\\Local\\Packages\\PythonSoftwareFoundation.Python.3.10_qbz5n2kfra8p0\\LocalCache\\local-packages\\Python310\\site-packages\\django\\test\\client.py\", line 836, in get\n    response = super().get(path, data=data, secure=secure, **extra)\n", "  File \"C:\\Users\\khali\\AppData\\Local\\Packages\\PythonSoftwareFoundation.Python.3.10_qbz5n2kfra8p0\\LocalCache\\local-packages\\Python310\\site-packages\\django\\test\\client.py\", line 424, in get\n    return self.generic(\n", "  File \"C:\\Users\\khali\\AppData\\Local\\Packages\\PythonSoftwareFoundation.Python.3.10_qbz5n2kfra8p0\\LocalCache\\local-packages\\Python310\\site-packages\\django\\test\\client.py\", line 541, in generic\n    return self.request(**r)\n", "  File \"C:\\Users\\khali\\AppData\\Local\\Packages\\PythonSoftwareFoundation.Python.3.10_qbz5n2kfra8p0\\LocalCache\\local-packages\\Python310\\site-packages\\django\\test\\client.py\", line 810, in request\n    self.check_exception(response)\n", "  File \"C:\\Users\\khali\\AppData\\Local\\Packages\\PythonSoftwareFoundation.Python.3.10_qbz5n2kfra8p0\\LocalCache\\local-packages\\Python310\\site-packages\\django\\test\\client.py\", line 663, in check_exception\n    raise exc_value\n", "  File \"C:\\Users\\khali\\AppData\\Local\\Packages\\PythonSoftwareFoundation.Python.3.10_qbz5n2kfra8p0\\LocalCache\\local-packages\\Python310\\site-packages\\django\\core\\handlers\\exception.py\", line 55, in inner\n    response = get_response(request)\n", "  File \"C:\\Users\\khali\\AppData\\Local\\Packages\\PythonSoftwareFoundation.Python.3.10_qbz5n2kfra8p0\\LocalCache\\local-packages\\Python310\\site-packages\\django\\core\\handlers\\base.py\", line 197, in _get_response\n    response = wrapped_callback(request, *callback_args, **callback_kwargs)\n"